[2025-03-08T00:27:59.489+0000] {local_task_job_runner.py:123} INFO - ::group::Pre task execution logs
[2025-03-08T00:27:59.537+0000] {taskinstance.py:2614} INFO - Dependencies all met for dep_context=non-requeueable deps ti=<TaskInstance: FPL_raw_teams.pull_data_from_api scheduled__2025-03-07T00:05:00+00:00 [queued]>
[2025-03-08T00:27:59.553+0000] {taskinstance.py:2614} INFO - Dependencies all met for dep_context=requeueable deps ti=<TaskInstance: FPL_raw_teams.pull_data_from_api scheduled__2025-03-07T00:05:00+00:00 [queued]>
[2025-03-08T00:27:59.554+0000] {taskinstance.py:2867} INFO - Starting attempt 1 of 4
[2025-03-08T00:27:59.586+0000] {taskinstance.py:2890} INFO - Executing <Task(_PythonDecoratedOperator): pull_data_from_api> on 2025-03-07 00:05:00+00:00
[2025-03-08T00:27:59.609+0000] {warnings.py:112} WARNING - /home/***/.local/lib/python3.12/site-packages/***/task/task_runner/standard_task_runner.py:70: DeprecationWarning: This process (pid=9124) is multi-threaded, use of fork() may lead to deadlocks in the child.
  pid = os.fork()

[2025-03-08T00:27:59.613+0000] {standard_task_runner.py:72} INFO - Started process 9142 to run task
[2025-03-08T00:27:59.609+0000] {standard_task_runner.py:104} INFO - Running: ['***', 'tasks', 'run', 'FPL_raw_teams', 'pull_data_from_api', 'scheduled__2025-03-07T00:05:00+00:00', '--job-id', '66', '--raw', '--subdir', 'DAGS_FOLDER/01_Bronze/01_FPL_raw_teams.py', '--cfg-path', '/tmp/tmpvj5volla']
[2025-03-08T00:27:59.623+0000] {standard_task_runner.py:105} INFO - Job 66: Subtask pull_data_from_api
[2025-03-08T00:27:59.772+0000] {task_command.py:467} INFO - Running <TaskInstance: FPL_raw_teams.pull_data_from_api scheduled__2025-03-07T00:05:00+00:00 [running]> on host 6fac9c74855d
[2025-03-08T00:28:00.022+0000] {taskinstance.py:3134} INFO - Exporting env vars: AIRFLOW_CTX_DAG_EMAIL='bobotieno99@gmail.com' AIRFLOW_CTX_DAG_OWNER='Fantasy Premier League' AIRFLOW_CTX_DAG_ID='FPL_raw_teams' AIRFLOW_CTX_TASK_ID='pull_data_from_api' AIRFLOW_CTX_EXECUTION_DATE='2025-03-07T00:05:00+00:00' AIRFLOW_CTX_TRY_NUMBER='1' AIRFLOW_CTX_DAG_RUN_ID='scheduled__2025-03-07T00:05:00+00:00'
[2025-03-08T00:28:00.025+0000] {taskinstance.py:732} INFO - ::endgroup::
[2025-03-08T04:41:01.841+0000] {01_FPL_raw_teams.py:62} ERROR - ‚ùå Error fetching data from API: HTTPSConnectionPool(host='fantasy.premierleague.com', port=443): Max retries exceeded with url: /api/bootstrap-static/ (Caused by SSLError(SSLEOFError(8, '[SSL: UNEXPECTED_EOF_WHILE_READING] EOF occurred in violation of protocol (_ssl.c:1010)')))
[2025-03-08T04:41:02.039+0000] {taskinstance.py:3313} ERROR - Task failed with exception
Traceback (most recent call last):
  File "/home/airflow/.local/lib/python3.12/site-packages/urllib3/connectionpool.py", line 464, in _make_request
    self._validate_conn(conn)
  File "/home/airflow/.local/lib/python3.12/site-packages/urllib3/connectionpool.py", line 1093, in _validate_conn
    conn.connect()
  File "/home/airflow/.local/lib/python3.12/site-packages/urllib3/connection.py", line 741, in connect
    sock_and_verified = _ssl_wrap_socket_and_match_hostname(
                        ^^^^^^^^^^^^^^^^^^^^^^^^^^^^^^^^^^^^
  File "/home/airflow/.local/lib/python3.12/site-packages/urllib3/connection.py", line 920, in _ssl_wrap_socket_and_match_hostname
    ssl_sock = ssl_wrap_socket(
               ^^^^^^^^^^^^^^^^
  File "/home/airflow/.local/lib/python3.12/site-packages/urllib3/util/ssl_.py", line 460, in ssl_wrap_socket
    ssl_sock = _ssl_wrap_socket_impl(sock, context, tls_in_tls, server_hostname)
               ^^^^^^^^^^^^^^^^^^^^^^^^^^^^^^^^^^^^^^^^^^^^^^^^^^^^^^^^^^^^^^^^^
  File "/home/airflow/.local/lib/python3.12/site-packages/urllib3/util/ssl_.py", line 504, in _ssl_wrap_socket_impl
    return ssl_context.wrap_socket(sock, server_hostname=server_hostname)
           ^^^^^^^^^^^^^^^^^^^^^^^^^^^^^^^^^^^^^^^^^^^^^^^^^^^^^^^^^^^^^^
  File "/usr/local/lib/python3.12/ssl.py", line 455, in wrap_socket
    return self.sslsocket_class._create(
           ^^^^^^^^^^^^^^^^^^^^^^^^^^^^^
  File "/usr/local/lib/python3.12/ssl.py", line 1041, in _create
    self.do_handshake()
  File "/usr/local/lib/python3.12/ssl.py", line 1319, in do_handshake
    self._sslobj.do_handshake()
ssl.SSLEOFError: [SSL: UNEXPECTED_EOF_WHILE_READING] EOF occurred in violation of protocol (_ssl.c:1010)

During handling of the above exception, another exception occurred:

Traceback (most recent call last):
  File "/home/airflow/.local/lib/python3.12/site-packages/urllib3/connectionpool.py", line 787, in urlopen
    response = self._make_request(
               ^^^^^^^^^^^^^^^^^^^
  File "/home/airflow/.local/lib/python3.12/site-packages/urllib3/connectionpool.py", line 488, in _make_request
    raise new_e
urllib3.exceptions.SSLError: [SSL: UNEXPECTED_EOF_WHILE_READING] EOF occurred in violation of protocol (_ssl.c:1010)

The above exception was the direct cause of the following exception:

Traceback (most recent call last):
  File "/home/airflow/.local/lib/python3.12/site-packages/requests/adapters.py", line 667, in send
    resp = conn.urlopen(
           ^^^^^^^^^^^^^
  File "/home/airflow/.local/lib/python3.12/site-packages/urllib3/connectionpool.py", line 841, in urlopen
    retries = retries.increment(
              ^^^^^^^^^^^^^^^^^^
  File "/home/airflow/.local/lib/python3.12/site-packages/urllib3/util/retry.py", line 519, in increment
    raise MaxRetryError(_pool, url, reason) from reason  # type: ignore[arg-type]
    ^^^^^^^^^^^^^^^^^^^^^^^^^^^^^^^^^^^^^^^^^^^^^^^^^^^
urllib3.exceptions.MaxRetryError: HTTPSConnectionPool(host='fantasy.premierleague.com', port=443): Max retries exceeded with url: /api/bootstrap-static/ (Caused by SSLError(SSLEOFError(8, '[SSL: UNEXPECTED_EOF_WHILE_READING] EOF occurred in violation of protocol (_ssl.c:1010)')))

During handling of the above exception, another exception occurred:

Traceback (most recent call last):
  File "/home/airflow/.local/lib/python3.12/site-packages/airflow/models/taskinstance.py", line 768, in _execute_task
    result = _execute_callable(context=context, **execute_callable_kwargs)
             ^^^^^^^^^^^^^^^^^^^^^^^^^^^^^^^^^^^^^^^^^^^^^^^^^^^^^^^^^^^^^
  File "/home/airflow/.local/lib/python3.12/site-packages/airflow/models/taskinstance.py", line 734, in _execute_callable
    return ExecutionCallableRunner(
           ^^^^^^^^^^^^^^^^^^^^^^^^
  File "/home/airflow/.local/lib/python3.12/site-packages/airflow/utils/operator_helpers.py", line 252, in run
    return self.func(*args, **kwargs)
           ^^^^^^^^^^^^^^^^^^^^^^^^^^
  File "/home/airflow/.local/lib/python3.12/site-packages/airflow/models/baseoperator.py", line 424, in wrapper
    return func(self, *args, **kwargs)
           ^^^^^^^^^^^^^^^^^^^^^^^^^^^
  File "/home/airflow/.local/lib/python3.12/site-packages/airflow/decorators/base.py", line 266, in execute
    return_value = super().execute(context)
                   ^^^^^^^^^^^^^^^^^^^^^^^^
  File "/home/airflow/.local/lib/python3.12/site-packages/airflow/models/baseoperator.py", line 424, in wrapper
    return func(self, *args, **kwargs)
           ^^^^^^^^^^^^^^^^^^^^^^^^^^^
  File "/home/airflow/.local/lib/python3.12/site-packages/airflow/operators/python.py", line 238, in execute
    return_value = self.execute_callable()
                   ^^^^^^^^^^^^^^^^^^^^^^^
  File "/home/airflow/.local/lib/python3.12/site-packages/airflow/operators/python.py", line 256, in execute_callable
    return runner.run(*self.op_args, **self.op_kwargs)
           ^^^^^^^^^^^^^^^^^^^^^^^^^^^^^^^^^^^^^^^^^^^
  File "/home/airflow/.local/lib/python3.12/site-packages/airflow/utils/operator_helpers.py", line 252, in run
    return self.func(*args, **kwargs)
           ^^^^^^^^^^^^^^^^^^^^^^^^^^
  File "/opt/airflow/dags/01_Bronze/01_FPL_raw_teams.py", line 43, in pull_data_from_api
    response = requests.get(api_url)
               ^^^^^^^^^^^^^^^^^^^^^
  File "/home/airflow/.local/lib/python3.12/site-packages/requests/api.py", line 73, in get
    return request("get", url, params=params, **kwargs)
           ^^^^^^^^^^^^^^^^^^^^^^^^^^^^^^^^^^^^^^^^^^^^
  File "/home/airflow/.local/lib/python3.12/site-packages/requests/api.py", line 59, in request
    return session.request(method=method, url=url, **kwargs)
           ^^^^^^^^^^^^^^^^^^^^^^^^^^^^^^^^^^^^^^^^^^^^^^^^^
  File "/home/airflow/.local/lib/python3.12/site-packages/requests/sessions.py", line 589, in request
    resp = self.send(prep, **send_kwargs)
           ^^^^^^^^^^^^^^^^^^^^^^^^^^^^^^
  File "/home/airflow/.local/lib/python3.12/site-packages/requests/sessions.py", line 703, in send
    r = adapter.send(request, **kwargs)
        ^^^^^^^^^^^^^^^^^^^^^^^^^^^^^^^
  File "/home/airflow/.local/lib/python3.12/site-packages/requests/adapters.py", line 698, in send
    raise SSLError(e, request=request)
requests.exceptions.SSLError: HTTPSConnectionPool(host='fantasy.premierleague.com', port=443): Max retries exceeded with url: /api/bootstrap-static/ (Caused by SSLError(SSLEOFError(8, '[SSL: UNEXPECTED_EOF_WHILE_READING] EOF occurred in violation of protocol (_ssl.c:1010)')))
[2025-03-08T04:41:06.428+0000] {taskinstance.py:1226} INFO - Marking task as UP_FOR_RETRY. dag_id=FPL_raw_teams, task_id=pull_data_from_api, run_id=scheduled__2025-03-07T00:05:00+00:00, execution_date=20250307T000500, start_date=20250308T002759, end_date=20250308T044106
[2025-03-08T04:41:06.877+0000] {job.py:229} INFO - Heartbeat recovered after 15189.74 seconds
[2025-03-08T04:41:07.308+0000] {warnings.py:112} WARNING - /home/***/.local/lib/python3.12/site-packages/***/utils/email.py:155: RemovedInAirflow3Warning: Fetching SMTP credentials from configuration variables will be deprecated in a future release. Please set credentials using a connection instead.
  send_mime_email(e_from=mail_from, e_to=recipients, mime_msg=msg, conn_id=conn_id, dryrun=dryrun)

[2025-03-08T04:41:07.417+0000] {configuration.py:1074} WARNING - section/key [smtp/smtp_user] not found in config
[2025-03-08T04:41:07.581+0000] {email.py:272} INFO - Email alerting: attempt 1
